
Original exception was:
Traceback (most recent call last):
  File "/f_c.py", line 2, in <module>
    print(format(float((f_c-32)/1.8), '.2f_c'))
ValueError: Invalid format specifier
